<?xml version="1.0"?>
<robot name="my_ur5">
  <link name="base_link">
    <visual>
      <origin xyz="0.0 0.0 0.0" rpy="0.0 0.0 0.0"/>
      <geometry>
        <mesh filename="package://my_robot/meshes/my_ur5/visual/base.dae"/>
      </geometry>
    </visual>
  </link>
  <joint name="shoulder_pan_joint" type="revolute">
    <origin xyz="0.0 0.0 0.06" rpy="0.0 0.0 0.0"/>
    <parent link="base_link"/>
    <child link="shoulder_link"/>
    <axis xyz="0.0 0.0 1.0"/>
    <limit lower="-6.28" upper="6.28" effort="150.0" velocity="3.14"/>
  </joint>
  <link name="shoulder_link">
    <visual name="">
      <origin xyz="0.0 0.0 0.0" rpy="0.0 0.0 0.0"/>
      <geometry>
        <mesh filename="package://my_robot/meshes/my_ur5/visual/shoulder.dae"/>
      </geometry>
    </visual>
  </link>
  <joint name="shoulder_lift_joint" type="revolute">
    <origin xyz="0.0 0.13585 0.0" rpy="0.0 1.5708 0.0"/>
    <parent link="shoulder_link"/>
    <child link="upper_arm_link"/>
    <axis xyz="0.0 1.0 0.0"/>
    <limit lower="-6.28" upper="6.28" effort="150.0" velocity="3.14"/>
  </joint>
  <link name="upper_arm_link">
    <visual name="">
      <origin xyz="0.0 0.0 0.0" rpy="0.0 0.0 0.0"/>
      <geometry>
        <mesh filename="package://my_robot/meshes/my_ur5/visual/upperarm.dae"/>
      </geometry>
    </visual>
  </link>
  <joint name="elbow_joint" type="revolute">
    <origin xyz="0.0 -0.1197 0.42500" rpy="0.0 0.0 0.0"/>
    <parent link="upper_arm_link"/>
    <child link="forearm_link"/>
    <axis xyz="0.0 1.0 0.0"/>
    <limit lower="-6.28" upper="6.28" effort="150.0" velocity="3.14"/>
  </joint>
  <link name="forearm_link">
    <visual name="">
      <origin xyz="0.0 0.0 0.0" rpy="0.0 0.0 0.0"/>
      <geometry>
        <mesh filename="package://my_robot/meshes/my_ur5/visual/forearm.dae"/>
      </geometry>
    </visual>
  </link>
  <joint name="wrist_1_joint" type="revolute">
    <origin xyz="0.0 0.0 0.39225" rpy="0.0 1.5708 0.0"/>
    <parent link="forearm_link"/>
    <child link="wrist_1_link"/>
    <axis xyz="0.0 1.0 0.0"/>
    <limit lower="-6.28" upper="6.28" effort="28.0" velocity="3.14"/>
  </joint>
  <link name="wrist_1_link">
    <visual name="">
      <origin xyz="0.0 0.0 0.0" rpy="0.0 0.0 0.0"/>
      <geometry>
        <mesh filename="package://my_robot/meshes/my_ur5/visual/wrist1.dae"/>
      </geometry>
    </visual>
  </link>
  <joint name="wrist_2_joint" type="revolute">
    <origin xyz="0.0 0.093 0.0" rpy="0.0 0.0 0.0"/>
    <parent link="wrist_1_link"/>
    <child link="wrist_2_link"/>
    <axis xyz="0.0 0.0 1.0"/>
    <limit lower="-6.28" upper="6.28" effort="28.0" velocity="3.14"/>
  </joint>
  <link name="wrist_2_link">
    <visual name="">
      <origin xyz="0.0 0.0 0.0" rpy="0.0 0.0 0.0"/>
      <geometry>
        <mesh filename="package://my_robot/meshes/my_ur5/visual/wrist2.dae"/>
      </geometry>
    </visual>
  </link>
  <joint name="wrist_3_joint" type="revolute">
    <origin xyz="0.0 0.0 0.09465" rpy="0.0 0.0 0.0"/>
    <parent link="wrist_2_link"/>
    <child link="wrist_3_link"/>
    <axis xyz="0.0 1.0 0.0"/>
    <limit lower="-6.28" upper="6.28" effort="28.0" velocity="3.14"/>
  </joint>
  <link name="wrist_3_link">
    <visual name="">
      <origin xyz="0.0 0.0 0.0" rpy="0.0 0.0 0.0"/>
      <geometry>
        <mesh filename="package://my_robot/meshes/my_ur5/visual/wrist3.dae"/>
      </geometry>
    </visual>
  </link>
</robot>