<?xml version="1.0" encoding="utf-8"?>
<!-- =================================================================================== -->
<!-- |    This document was autogenerated by xacro from iai_donbot_unreal_no_odom.xacro | -->
<!-- |    EDITING THIS FILE BY HAND IS NOT RECOMMENDED                                 | -->
<!-- =================================================================================== -->
<robot name="iai_donbot">
  <!--xacro:include filename="$(find iai_ur_description)/urdf/ur.transmission.xacro" /-->
  <!--xacro:include filename="$(find iai_ur_description)/urdf/ur.gazebo.xacro" /-->
  <!--xacro:property name="pi" value="3.14159265" /-->
  <!-- measured from model -->
  <!--property name="shoulder_height" value="0.089159" /-->
  <!--property name="shoulder_offset" value="0.13585" /-->
  <!-- shoulder_offset - elbow_offset + wrist_1_length = 0.10915 -->
  <!--property name="upper_arm_length" value="0.42500" /-->
  <!--property name="elbow_offset" value="0.1197" /-->
  <!-- CAD measured -->
  <!--property name="forearm_length" value="0.39225" /-->
  <!--property name="wrist_1_length" value="0.093" /-->
  <!-- CAD measured -->
  <!--property name="wrist_2_length" value="0.09465" /-->
  <!-- In CAD this distance is 0.930, but in the spec it is 0.09465 -->
  <!--property name="wrist_3_length" value="0.0823" /-->
  <!-- manually measured -->
  <!-- Definition of base_footprint -> base_link -->
  <link name="base_footprint">
    <inertial>
      <origin rpy="0.0 0.0 0.0" xyz="0.0 0.0 0.0"/>
      <mass value="1E-4"/>
      <inertia ixx="1E-4" ixy="0.0" ixz="0.0" iyy="1E-4" iyz="0.0" izz="1E-4"/>
    </inertial>
    <visual>
      <origin rpy="0 0 0" xyz="0 0 0"/>
      <geometry>
        <box size="0.01 0.01 0.01"/>
      </geometry>
      <material name="White"/>
    </visual>
  </link>
  <!-- JOINT to define base_footprint -->
  <joint name="base_footprint_joint" type="fixed">
    <!-- Explanation of the calculations to find base_link relative
        to /base_footprint.

        /base_footprint is on the floor, exactly in the center of the four wheels to
        simplify the odometry and FK/IK calculations of the base.
        Orientation: X pointing forward, and Z up.

        /base_link is on the front left upper corner of the main alu enclosure.
            with the same orientation as /base_footprint

        X:  wheel-axis to wheel-axis distance = 789.5mm.
            Distance front wheel axis to plane where base_link is: 139.5mm
            X = 789.5/2 - 139.5 = 255.25mm
    
        Y:  main alu enclosure is 450mm wide, and the
            center of the wheels is also the center of the alu enclosure, 
            so half is Y = 225mm.

        Z:   base_link is at the top of a 120mm plate.
            The wheels are aligned with the center of the plate.
            The wheels are 8", so base_link is 
            Z = 60+4*25.4mm = 161.6mm (above the floor).
        -->
    <origin rpy="0 0 0" xyz="0.25525 0.225 0.1616"/>
    <parent link="base_footprint"/>
    <child link="base_link"/>
  </joint>
  <link name="base_link">
    <inertial>
      <origin rpy="0 0 0" xyz="-0.257082749974343 -0.227847593519202 0.0535404411050965"/>
      <mass value="70.0210745907357"/>
      <inertia ixx="9.06122735721955" ixy="0.0933988942518672" ixz="0.665662584048376" iyy="12.5350462868938" iyz="0.00262520723302998" izz="7.44839974564544"/>
    </inertial>
    <visual>
      <origin rpy="0 0 0" xyz="0 0 0"/>
      <geometry>
        <!-- <mesh -->
        <mesh filename="package://iai_donbot_description/meshes/iai_boxy_base_2/base.stl"/>
      </geometry>
      <material name="">
        <color rgba="0.792156862745098 0.819607843137255 0.933333333333333 1"/>
      </material>
    </visual>
    <collision>
      <origin rpy="0 0 0" xyz="0 0 0"/>
      <geometry>
        <mesh filename="package://iai_donbot_description/meshes/iai_boxy_base_2/base_lowres.stl"/>
      </geometry>
    </collision>
  </link>
  <link name="laser_reference_front"/>
  <joint name="laser_reference_front_joint" type="fixed">
    <origin rpy="0.0 0.0 0.7853975" xyz="0.1772 0.060215 0.149929"/>
    <parent link="base_link"/>
    <child link="laser_reference_front"/>
    <axis xyz="0.0 0.0 0.0"/>
  </joint>
  <link name="laser_reference_back"/>
  <joint name="laser_reference_back_joint" type="fixed">
    <origin rpy="4.9333E-15 4.5082E-15 -2.3562" xyz="-0.69357 -0.506 0.1575"/>
    <parent link="base_link"/>
    <child link="laser_reference_back"/>
    <axis xyz="-1 0 0"/>
  </joint>
  <link name="plate">
    <visual>
      <origin rpy="0 0 0" xyz="0 0 0"/>
      <geometry>
        <box size="0.6 0.553 0.02"/>
      </geometry>
      <material name="White"/>
    </visual>
    <collision>
      <origin rpy="0 0 0" xyz="0 0 0"/>
      <geometry>
        <box size="0.6 0.553 0.02"/>
      </geometry>
    </collision>
  </link>
  <!-- JOINT to define base_footprint -->
  <joint name="plate_joint" type="fixed">
    <origin rpy="0 0 0" xyz="-0.300 -0.230 0.460"/>
    <parent link="base_link"/>
    <child link="plate"/>
  </joint>
  <material name="gray">
    <color rgba="0.56 0.67 0.67 1"/>
  </material>
  <material name="Silver">
    <color rgba="1.0 1.0 1.0 1.0"/>
  </material>
  <material name="Grey">
    <color rgba="0.7 0.7 0.7 1.0"/>
  </material>
  <material name="yellow">
    <color rgba="1.0 1.0 0.0 1.0"/>
  </material>
  <link name="ur5_base_link">
    <visual>
      <geometry>
        <mesh filename="package://iai_donbot_description/meshes/ur5/visual/base.dae"/>
      </geometry>
      <material name="LightGrey">
        <color rgba="0.7 0.7 0.7 1.0"/>
      </material>
    </visual>
    <collision>
      <geometry>
        <mesh filename="package://iai_donbot_description/meshes/ur5/collision/base.stl"/>
      </geometry>
    </collision>
    <inertial>
      <mass value="4.0"/>
      <origin rpy="0 0 0" xyz="0.0 0.0 0.0"/>
      <inertia ixx="0.00443333156" ixy="0.0" ixz="0.0" iyy="0.00443333156" iyz="0.0" izz="0.0072"/>
    </inertial>
  </link>
  <joint name="ur5_shoulder_pan_joint" type="revolute">
    <parent link="ur5_base_link"/>
    <child link="ur5_shoulder_link"/>
    <origin rpy="0.0 0.0 0.0" xyz="0.0 0.0 0.089159"/>
    <axis xyz="0 0 1"/>
    <limit effort="150.0" lower="-6.28318530718" upper="6.28318530718" velocity="3.15"/>
    <dynamics damping="0.0" friction="0.0"/>
  </joint>
  <link name="ur5_shoulder_link">
    <visual>
      <geometry>
        <mesh filename="package://iai_donbot_description/meshes/ur5/visual/shoulder.dae"/>
      </geometry>
      <material name="LightGrey">
        <color rgba="0.7 0.7 0.7 1.0"/>
      </material>
    </visual>
    <collision>
      <geometry>
        <mesh filename="package://iai_donbot_description/meshes/ur5/collision/shoulder.stl"/>
      </geometry>
    </collision>
    <inertial>
      <mass value="3.7"/>
      <origin rpy="0 0 0" xyz="0.0 0.0 0.0"/>
      <inertia ixx="0.010267495893" ixy="0.0" ixz="0.0" iyy="0.010267495893" iyz="0.0" izz="0.00666"/>
    </inertial>
  </link>
  <joint name="ur5_shoulder_lift_joint" type="revolute">
    <parent link="ur5_shoulder_link"/>
    <child link="ur5_upper_arm_link"/>
    <origin rpy="0.0 1.57079632679 0.0" xyz="0.0 0.13585 0.0"/>
    <axis xyz="0 1 0"/>
    <limit effort="150.0" lower="-6.28318530718" upper="6.28318530718" velocity="3.15"/>
    <dynamics damping="0.0" friction="0.0"/>
  </joint>
  <link name="ur5_upper_arm_link">
    <visual>
      <geometry>
        <mesh filename="package://iai_donbot_description/meshes/ur5/visual/upperarm.dae"/>
      </geometry>
      <material name="LightGrey">
        <color rgba="0.7 0.7 0.7 1.0"/>
      </material>
    </visual>
    <collision>
      <geometry>
        <mesh filename="package://iai_donbot_description/meshes/ur5/collision/upperarm.stl"/>
      </geometry>
    </collision>
    <inertial>
      <mass value="8.393"/>
      <origin rpy="0 0 0" xyz="0.0 0.0 0.28"/>
      <inertia ixx="0.22689067591" ixy="0.0" ixz="0.0" iyy="0.22689067591" iyz="0.0" izz="0.0151074"/>
    </inertial>
  </link>
  <joint name="ur5_elbow_joint" type="revolute">
    <parent link="ur5_upper_arm_link"/>
    <child link="ur5_forearm_link"/>
    <origin rpy="0.0 0.0 0.0" xyz="0.0 -0.1197 0.425"/>
    <axis xyz="0 1 0"/>
    <limit effort="150.0" lower="-6.28318530718" upper="6.28318530718" velocity="3.15"/>
    <dynamics damping="0.0" friction="0.0"/>
  </joint>
  <link name="ur5_forearm_link">
    <visual>
      <geometry>
        <mesh filename="package://iai_donbot_description/meshes/ur5/visual/forearm.dae"/>
      </geometry>
      <material name="LightGrey">
        <color rgba="0.7 0.7 0.7 1.0"/>
      </material>
    </visual>
    <collision>
      <geometry>
        <mesh filename="package://iai_donbot_description/meshes/ur5/collision/forearm.stl"/>
      </geometry>
    </collision>
    <inertial>
      <mass value="2.275"/>
      <origin rpy="0 0 0" xyz="0.0 0.0 0.25"/>
      <inertia ixx="0.049443313556" ixy="0.0" ixz="0.0" iyy="0.049443313556" iyz="0.0" izz="0.004095"/>
    </inertial>
  </link>
  <joint name="ur5_wrist_1_joint" type="revolute">
    <parent link="ur5_forearm_link"/>
    <child link="ur5_wrist_1_link"/>
    <origin rpy="0.0 1.57079632679 0.0" xyz="0.0 0.0 0.39225"/>
    <axis xyz="0 1 0"/>
    <limit effort="28.0" lower="-6.28318530718" upper="6.28318530718" velocity="3.2"/>
    <dynamics damping="0.0" friction="0.0"/>
  </joint>
  <link name="ur5_wrist_1_link">
    <visual>
      <geometry>
        <mesh filename="package://iai_donbot_description/meshes/ur5/visual/wrist1.dae"/>
      </geometry>
      <material name="LightGrey">
        <color rgba="0.7 0.7 0.7 1.0"/>
      </material>
    </visual>
    <collision>
      <geometry>
        <mesh filename="package://iai_donbot_description/meshes/ur5/collision/wrist1.stl"/>
      </geometry>
    </collision>
    <inertial>
      <mass value="1.219"/>
      <origin rpy="0 0 0" xyz="0.0 0.0 0.0"/>
      <inertia ixx="0.111172755531" ixy="0.0" ixz="0.0" iyy="0.111172755531" iyz="0.0" izz="0.21942"/>
    </inertial>
  </link>
  <joint name="ur5_wrist_2_joint" type="revolute">
    <parent link="ur5_wrist_1_link"/>
    <child link="ur5_wrist_2_link"/>
    <origin rpy="0.0 0.0 0.0" xyz="0.0 0.093 0.0"/>
    <axis xyz="0 0 1"/>
    <limit effort="28.0" lower="-6.28318530718" upper="6.28318530718" velocity="3.2"/>
    <dynamics damping="0.0" friction="0.0"/>
  </joint>
  <link name="ur5_wrist_2_link">
    <visual>
      <geometry>
        <mesh filename="package://iai_donbot_description/meshes/ur5/visual/wrist2.dae"/>
      </geometry>
      <material name="LightGrey">
        <color rgba="0.7 0.7 0.7 1.0"/>
      </material>
    </visual>
    <collision>
      <geometry>
        <mesh filename="package://iai_donbot_description/meshes/ur5/collision/wrist2.stl"/>
      </geometry>
    </collision>
    <inertial>
      <mass value="1.219"/>
      <origin rpy="0 0 0" xyz="0.0 0.0 0.0"/>
      <inertia ixx="0.111172755531" ixy="0.0" ixz="0.0" iyy="0.111172755531" iyz="0.0" izz="0.21942"/>
    </inertial>
  </link>
  <joint name="ur5_wrist_3_joint" type="revolute">
    <parent link="ur5_wrist_2_link"/>
    <child link="ur5_wrist_3_link"/>
    <origin rpy="0.0 0.0 0.0" xyz="0.0 0.0 0.09465"/>
    <axis xyz="0 1 0"/>
    <limit effort="28.0" lower="-6.28318530718" upper="6.28318530718" velocity="3.2"/>
    <dynamics damping="0.0" friction="0.0"/>
  </joint>
  <link name="ur5_wrist_3_link">
    <visual>
      <geometry>
        <mesh filename="package://iai_donbot_description/meshes/ur5/visual/wrist3.dae"/>
      </geometry>
      <material name="LightGrey">
        <color rgba="0.7 0.7 0.7 1.0"/>
      </material>
    </visual>
    <collision>
      <geometry>
        <mesh filename="package://iai_donbot_description/meshes/ur5/collision/wrist3.stl"/>
      </geometry>
    </collision>
    <inertial>
      <mass value="0.1879"/>
      <origin rpy="0 0 0" xyz="0.0 0.0 0.0"/>
      <inertia ixx="0.0171364731454" ixy="0.0" ixz="0.0" iyy="0.0171364731454" iyz="0.0" izz="0.033822"/>
    </inertial>
  </link>
  <joint name="ur5_ee_fixed_joint" type="fixed">
    <parent link="ur5_wrist_3_link"/>
    <child link="ur5_ee_link"/>
    <origin rpy="0.0 0.0 1.57079632679" xyz="0.0 0.0823 0.0"/>
  </joint>
  <link name="ur5_ee_link">
    <collision>
      <geometry>
        <box size="0.01 0.01 0.01"/>
      </geometry>
      <origin rpy="0 0 0" xyz="-0.01 0 0"/>
    </collision>
  </link>
  <!--xacro:ur_arm_transmission prefix="${prefix}" /-->
  <!--xacro:ur_arm_gazebo prefix="${prefix}" /-->
  <!-- ROS base_link to UR 'Base' Coordinates transform -->
  <link name="ur5_base"/>
  <joint name="ur5_base_link-base_fixed_joint" type="fixed">
    <!-- NOTE: this rotation is only needed as long as base_link itself is
                 not corrected wrt the real robot (ie: rotated over 180
                 degrees)
      -->
    <origin rpy="0 0 -3.14159265359" xyz="0 0 0"/>
    <parent link="ur5_base_link"/>
    <child link="ur5_base"/>
  </joint>
  <!-- Frame coincident with all-zeros TCP on UR controller -->
  <link name="ur5_tool0"/>
  <joint name="ur5_wrist_3_link-tool0_fixed_joint" type="fixed">
    <origin rpy="-1.57079632679 0 0" xyz="0 0.0823 0"/>
    <parent link="ur5_wrist_3_link"/>
    <child link="ur5_tool0"/>
  </joint>
  <joint name="arm_base_mounting_joint" type="fixed">
    <parent link="base_link"/>
    <child link="ur5_base_link"/>
    <origin rpy="0.0 0.0 0.0" xyz="-0.525 -0.424 0.470"/>
  </joint>
  <link name="kms_mounting_plate">
    <visual>
      <geometry>
        <mesh filename="package://iai_donbot_description/meshes/iai_table_robot/adapter_plate_iso50_kms40_weiss.stl" scale="0.001 0.001 0.001"/>
      </geometry>
      <material name="gray"/>
    </visual>
  </link>
  <joint name="kms_mounting_plate_joint" type="fixed">
    <parent link="ur5_ee_link"/>
    <child link="kms_mounting_plate"/>
    <origin rpy="0 1.57079632679 0" xyz="0 0 0"/>
  </joint>
  <!-- Joint connecting the parent to our frame_in -->
  <joint name="adapter_iso50_kms40_joint" type="fixed">
    <origin rpy="0 0 3.14159265359" xyz="0 0 0"/>
    <parent link="kms_mounting_plate"/>
    <child link="adapter_iso50_kms40_frame_in"/>
  </joint>
  <!-- link for the adapter plate -->
  <link name="adapter_iso50_kms40_frame_in">
    <visual>
      <origin rpy="0 0 0" xyz="0 0 0"/>
      <geometry>
        <mesh filename="package://iai_donbot_description/meshes/iai_kms_40/adapter_plate_iso50_kms40_weiss.stl" scale="0.001 0.001 0.001"/>
      </geometry>
      <material name="Grey"/>
    </visual>
  </link>
  <!-- Empty link just to get the frame out -->
  <link name="adapter_iso50_kms40_frame_out"/>
  <!-- joint positioning the frame_out -->
  <joint name="adapter_iso50_kms40_trans_frame_out" type="fixed">
    <origin rpy="0 0 0" xyz="0 0 0.016"/>
    <parent link="adapter_iso50_kms40_frame_in"/>
    <child link="adapter_iso50_kms40_frame_out"/>
    <axis xyz="0 0 0"/>
  </joint>
  <!-- Now joint connecting the actual kms40 sensor -->
  <joint name="kms40_joint" type="fixed">
    <origin rpy="0 0 0" xyz="0 0 0"/>
    <parent link="adapter_iso50_kms40_frame_out"/>
    <child link="kms40_frame_in"/>
  </joint>
  <!-- Link for the kms40 sensor-->
  <link name="kms40_frame_in">
    <visual>
      <origin rpy="0 0 0" xyz="0 0 0"/>
      <geometry>
        <mesh filename="package://iai_donbot_description/meshes/iai_kms_40/kms40_simple.stl" scale="0.001 0.001 0.001"/>
      </geometry>
      <material name="Grey"/>
    </visual>
  </link>
  <!-- Empty link just to get the frame out -->
  <!-- This is also the reference frame for the force/torque data -->
  <link name="kms40_frame_out"/>
  <!-- joint positioning the frame_out -->
  <joint name="kms40_trans_frame_out" type="fixed">
    <origin rpy="0 0 0" xyz="0 0 0.027"/>
    <parent link="kms40_frame_in"/>
    <child link="kms40_frame_out"/>
    <axis xyz="0 0 0"/>
  </joint>
  <!-- Joint connecting the parent to our frame_in -->
  <joint name="adapter_kms40_fwk050_in_joint" type="fixed">
    <origin rpy="0 0 0" xyz="0 0 0"/>
    <parent link="kms40_frame_out"/>
    <child link="adapter_kms40_fwk050_frame_in"/>
  </joint>
  <link name="adapter_kms40_fwk050_frame_in">
    <visual>
      <origin rpy="0 0 0" xyz="0 0 0"/>
      <geometry>
        <!-- these meshes were exported in mm, so scale back to m -->
        <mesh filename="package://iai_donbot_description/meshes/iai_adapters/adapter_kms40_fwk050.stl" scale="0.001 0.001 0.001"/>
      </geometry>
      <material name="Grey"/>
    </visual>
  </link>
  <!-- Empty link just to get the frame out -->
  <link name="adapter_kms40_fwk050_frame_out"/>
  <!-- joint positioning the frame_out -->
  <joint name="adapter_kms40_fwk050_trans_frame_out" type="fixed">
    <origin rpy="0 0 0" xyz="0 0 0.01"/>
    <parent link="adapter_kms40_fwk050_frame_in"/>
    <child link="adapter_kms40_fwk050_frame_out"/>
    <axis xyz="0 0 0"/>
  </joint>
  <!-- The joint connecting us to the next part of the chain is in the next URDF -->
  <!-- Joint connecting the parent to our frame_in -->
  <joint name="fwk_fwa_050_in_joint" type="fixed">
    <origin rpy="0 0 0" xyz="0 0 0"/>
    <parent link="adapter_kms40_fwk050_frame_out"/>
    <child link="fwk_fwa_050_frame_in"/>
  </joint>
  <link name="fwk_fwa_050_frame_in">
    <visual>
      <origin rpy="0 0 0" xyz="0 0 0"/>
      <geometry>
        <!-- these meshes were exported in mm, so scale back to m -->
        <mesh filename="package://iai_donbot_description/meshes/iai_adapters/fwk_fwa_050_simple.stl" scale="0.001 0.001 0.001"/>
      </geometry>
      <material name="Grey"/>
    </visual>
  </link>
  <!-- Empty link just to get the frame out -->
  <link name="fwk_fwa_050_frame_out"/>
  <!-- joint positioning the frame_out -->
  <joint name="fwk_fwa_050_trans_frame_out" type="fixed">
    <origin rpy="0 0 0" xyz="0 0 0.0141"/>
    <parent link="fwk_fwa_050_frame_in"/>
    <child link="fwk_fwa_050_frame_out"/>
    <axis xyz="0 0 0"/>
  </joint>
  <!-- The joint connecting us to the next part of the chain is in the next URDF -->
  <!-- Joint connecting the parent to our frame_in -->
  <joint name="adapter_fwa050_wsg50_in_joint" type="fixed">
    <origin rpy="0 0 0" xyz="0 0 0.0"/>
    <parent link="fwk_fwa_050_frame_out"/>
    <child link="adapter_fwa050_wsg50_frame_in"/>
  </joint>
  <link name="adapter_fwa050_wsg50_frame_in">
    <visual>
      <origin rpy="0 0 0" xyz="0 0 0"/>
      <geometry>
        <!-- these meshes were exported in mm, so scale back to m -->
        <mesh filename="package://iai_donbot_description/meshes/iai_adapters/adapter_fwa050_wsg50.stl" scale="0.001 0.001 0.001"/>
      </geometry>
      <material name="Grey"/>
    </visual>
  </link>
  <!-- Empty link just to get the frame out -->
  <link name="adapter_fwa050_wsg50_frame_out"/>
  <!-- joint positioning the frame_out -->
  <joint name="adapter_fwa050_wsg50_trans_frame_out" type="fixed">
    <origin rpy="0 0 0" xyz="0 0 0.01"/>
    <parent link="adapter_fwa050_wsg50_frame_in"/>
    <child link="adapter_fwa050_wsg50_frame_out"/>
    <axis xyz="0 0 0"/>
  </joint>
  <!-- The joint connecting us to the next part of the chain is in the next URDF -->
  <joint name="gripper_anterior_gripper_joint" type="fixed">
    <origin rpy="0 0 3.14159265359" xyz="0 0 0"/>
    <parent link="adapter_fwa050_wsg50_frame_out"/>
    <child link="gripper_base_link"/>
  </joint>
  <!-- BASE LINK -->
  <link name="gripper_base_link">
    <inertial>
      <mass value="0.25"/>
      <origin xyz="0 0 0"/>
      <inertia ixx="1.0" ixy="0.0" ixz="0.0" iyy="1.0" iyz="0.0" izz="1.0"/>
    </inertial>
    <visual>
      <origin rpy="0 0 0" xyz="0.0 0 0"/>
      <geometry>
        <mesh filename="package://iai_donbot_description/meshes/iai_wsg_50/WSG50_110.stl" scale="1 1 1"/>
      </geometry>
      <material name="grey">
        <color rgba="0.5 0.5 0.5 1"/>
      </material>
    </visual>
    <collision>
      <origin rpy="0 0 0" xyz="0.0 0 0"/>
      <geometry>
        <mesh filename="package://iai_donbot_description/meshes/iai_wsg_50/WSG50_110.stl" scale="1 1 1"/>
      </geometry>
    </collision>
  </link>
  <!-- GRIPPER LEFT -->
  <joint name="gripper_base_gripper_left_joint" type="prismatic">
    <limit effort="10.0" lower="-0.051" upper="0" velocity="0.42"/>
    <origin rpy="0 0 0" xyz="-0.0040 0 0"/>
    <parent link="gripper_base_link"/>
    <child link="gripper_gripper_left_link"/>
    <dynamics damping="1" friction="1"/>
    <axis xyz="1 0 0"/>
  </joint>
  <link name="gripper_gripper_left_link">
    <inertial>
      <mass value="0.001"/>
      <origin xyz="0 0 0"/>
      <inertia ixx="1.0" ixy="0.0" ixz="0.0" iyy="1.0" iyz="0.0" izz="1.0"/>
    </inertial>
    <visual>
      <origin rpy="0 0 0" xyz="0.0 0 0"/>
      <geometry>
        <mesh filename="package://iai_donbot_description/meshes/iai_wsg_50/GUIDE_WSG50_110.stl" scale="0.001 0.001 0.001"/>
      </geometry>
      <material name="black">
        <color rgba="0 0 0 1"/>
      </material>
    </visual>
    <collision>
      <origin rpy="0 0 0" xyz="0 0 0"/>
      <geometry>
        <mesh filename="package://iai_donbot_description/meshes/iai_wsg_50/GUIDE_WSG50_110.stl" scale="0.001 0.001 0.001"/>
      </geometry>
    </collision>
  </link>
  <!-- LEFT FINGER -->
  <joint name="gripper_guide_joint_finger_left" type="fixed">
    <origin rpy="0 0 0" xyz="0 0 0.023"/>
    <parent link="gripper_gripper_left_link"/>
    <child link="gripper_finger_left_link"/>
    <dynamics damping="1" friction="1"/>
    <axis xyz="1 0 0"/>
  </joint>
  <link name="gripper_finger_left_link">
    <inertial>
      <mass value="0.001"/>
      <origin xyz="0 0 0"/>
      <inertia ixx="1.0" ixy="0.0" ixz="0.0" iyy="1.0" iyz="0.0" izz="1.0"/>
    </inertial>
    <visual>
      <origin rpy="0 0 0" xyz="0.0 0 0"/>
      <geometry>
        <mesh filename="package://iai_donbot_description/meshes/iai_wsg_50/WSG-FMF.stl" scale="0.001 0.001 0.001"/>
      </geometry>
      <material name="black">
        <color rgba="0 0 0 1"/>
      </material>
    </visual>
    <collision>
      <origin rpy="0 0 0" xyz="0 0 0"/>
      <geometry>
        <mesh filename="package://iai_donbot_description/meshes/iai_wsg_50/WSG-FMF.stl" scale="0.001 0.001 0.001"/>
      </geometry>
    </collision>
    <contact_coefficients kd="1.0" kp="1000.0" mu="0"/>
  </link>
  <!-- GRIPPER RIGHT -->
  <joint name="gripper_base_gripper_right_joint" type="prismatic">
    <limit effort="10.0" lower="0" upper="0.051" velocity="0.42"/>
    <origin rpy="0 0 3.14159265359" xyz="0.0040 0 0"/>
    <parent link="gripper_base_link"/>
    <child link="gripper_gripper_right_link"/>
    <axis xyz="-1 0 0"/>
    <dynamics damping="1" friction="1"/>
  </joint>
  <link name="gripper_gripper_right_link">
    <inertial>
      <mass value="0.001"/>
      <origin xyz="0 0 0"/>
      <inertia ixx="1.0" ixy="0.0" ixz="0.0" iyy="1.0" iyz="0.0" izz="1.0"/>
    </inertial>
    <visual>
      <origin rpy="0 0 0" xyz="0.0 0 0"/>
      <geometry>
        <mesh filename="package://iai_donbot_description/meshes/iai_wsg_50/GUIDE_WSG50_110.stl" scale="0.001 0.001 0.001"/>
        <!--box size="0.0175 0.03 0.024"/-->
      </geometry>
      <material name="black">
        <color rgba="0 0 0 1"/>
      </material>
    </visual>
    <collision>
      <origin rpy="0 0 0" xyz="0 0 0"/>
      <geometry>
        <!--box size="0.0175 0.03 0.024"/-->
        <mesh filename="package://iai_donbot_description/meshes/iai_wsg_50/GUIDE_WSG50_110.stl" scale="0.001 0.001 0.001"/>
      </geometry>
    </collision>
  </link>
  <!-- RIGHT FINGER -->
  <joint name="gripper_guide_joint_finger_right" type="fixed">
    <origin rpy="0 0 0" xyz="0 0 0.023"/>
    <parent link="gripper_gripper_right_link"/>
    <child link="gripper_finger_right_link"/>
  </joint>
  <link name="gripper_finger_right_link">
    <inertial>
      <mass value="0.001"/>
      <origin xyz="0 0 0"/>
      <inertia ixx="1.0" ixy="0.0" ixz="0.0" iyy="1.0" iyz="0.0" izz="1.0"/>
    </inertial>
    <visual>
      <origin rpy="0 0 0" xyz="0.0 0 0"/>
      <geometry>
        <mesh filename="package://iai_donbot_description/meshes/iai_wsg_50/WSG-FMF.stl" scale="0.001 0.001 0.001"/>
      </geometry>
      <material name="black">
        <color rgba="0 0 0 1"/>
      </material>
    </visual>
    <collision>
      <origin rpy="0 0 0" xyz="0 0 0"/>
      <geometry>
        <mesh filename="package://iai_donbot_description/meshes/iai_wsg_50/WSG-FMF.stl" scale="0.001 0.001 0.001"/>
      </geometry>
    </collision>
    <contact_coefficients kd="1.0" kp="1000.0" mu="0"/>
  </link>
  <link name="gripper_tool_frame"/>
  <joint name="gripper_tool_frame_joint" type="fixed">
    <origin rpy="0 0 0" xyz="0 0 0.144"/>
    <parent link="gripper_base_link"/>
    <child link="gripper_tool_frame"/>
  </joint>
  <link name="camera_holder_link">
    <visual>
      <geometry>
        <mesh filename="package://iai_donbot_description/meshes/iai_refills_camera/refills_camera_holder_and_camera.stl" scale="1 1 1"/>
      </geometry>
      <material name="gray"/>
    </visual>
    <collision>
      <geometry>
        <mesh filename="package://iai_donbot_description/meshes/iai_refills_camera/refills_camera_holder_and_camera.stl" scale="1 1 1"/>
      </geometry>
      <material name="gray"/>
    </collision>
  </link>
  <joint name="gripper_to_camera_holder_joint" type="fixed">
    <parent link="gripper_base_link"/>
    <child link="camera_holder_link"/>
    <origin rpy="0 0 3.14159265359" xyz="0 0 0"/>
  </joint>
  <link name="camera_link">
    <visual>
      <geometry>
        <cylinder length="0.005" radius="0.001"/>
      </geometry>
    </visual>
  </link>
  <joint name="gripper_to_camera_joint" type="fixed">
    <parent link="gripper_base_link"/>
    <child link="camera_link"/>
    <origin rpy="0.204429 6.281375 3.127197" xyz="0.002956 -0.066498 0.060947"/>
  </joint>
  <link name="rs_camera_link"/>
  <joint name="wristcam_to_realsense_joint" type="fixed">
    <parent link="camera_link"/>
    <child link="rs_camera_link"/>
    <origin rpy="6.270618 4.930698 1.578454" xyz="-0.017993 -0.107556 0.017699"/>
  </joint>
  <!-- boxes to cover up switches and stuff -->
  <joint name="switches_joint" type="fixed">
    <parent link="base_link"/>
    <child link="switches"/>
    <origin rpy="0 0 0" xyz="-0.66 -0.225 0.225"/>
  </joint>
  <link name="switches">
    <visual>
      <geometry>
        <box size="0.12 0.4 0.45"/>
      </geometry>
      <material name="Silver"/>
    </visual>
    <collision>
      <geometry>
        <box size="0.12 0.4 0.45"/>
      </geometry>
      <material name="Silver"/>
    </collision>
  </link>
  <joint name="charger_joint" type="fixed">
    <parent link="base_link"/>
    <child link="charger"/>
    <origin rpy="0 0 0" xyz="0.075 -0.225 0.19"/>
  </joint>
  <link name="charger">
    <visual>
      <geometry>
        <box size="0.15 0.3 0.38"/>
      </geometry>
      <material name="Silver"/>
    </visual>
    <collision>
      <geometry>
        <box size="0.15 0.3 0.38"/>
      </geometry>
      <material name="Silver"/>
    </collision>
  </link>
  <joint name="e_stop_joint" type="fixed">
    <parent link="base_link"/>
    <child link="e_stop"/>
    <origin rpy="0 0 0" xyz="-0.035 -0.0015 0.52"/>
  </joint>
  <link name="e_stop">
    <visual>
      <geometry>
        <box size="0.07 0.07 0.1"/>
      </geometry>
      <material name="yellow"/>
    </visual>
    <collision>
      <geometry>
        <box size="0.07 0.07 0.1"/>
      </geometry>
      <material name="yellow"/>
    </collision>
  </link>
  <joint name="wlan_joint" type="fixed">
    <parent link="base_link"/>
    <child link="wlan"/>
    <origin rpy="0 -0.314 0" xyz="0.05 -0.225 0.405"/>
  </joint>
  <link name="wlan">
    <visual>
      <geometry>
        <box size="0.25 0.14 0.05"/>
      </geometry>
      <material name="Silver"/>
    </visual>
    <collision>
      <geometry>
        <box size="0.25 0.14 0.05"/>
      </geometry>
      <material name="Silver"/>
    </collision>
  </link>
  <joint name="ur5_touchpad_joint" type="fixed">
    <parent link="base_link"/>
    <child link="ur5_touchpad"/>
    <origin rpy="0 0 0" xyz="-0.16 -0.5355 0.38"/>
  </joint>
  <link name="ur5_touchpad">
    <visual>
      <geometry>
        <box size="0.32 0.06 0.24"/>
      </geometry>
      <material name="Silver"/>
    </visual>
    <collision>
      <geometry>
        <box size="0.32 0.06 0.24"/>
      </geometry>
      <material name="Silver"/>
    </collision>
  </link>
  <joint name="wrist_collision_joint" type="fixed">
    <parent link="adapter_kms40_fwk050_frame_in"/>
    <child link="wrist_collision"/>
    <origin rpy="0 0 0" xyz="0 0 -0.005"/>
  </joint>
  <link name="wrist_collision">
    <collision>
      <geometry>
        <cylinder length="0.08" radius="0.04"/>
      </geometry>
      <material name="Silver"/>
    </collision>
  </link>
</robot>

